<?xml version="1.0" ?>
<robot name="cartpole">
  <!-- <<<<<<<<<<<<<<< TABLE >>>>>>>>>>>>>>> -->
  <link name="table">
    <inertial>
      <mass value="0" />
      <inertia ixx = "999" iyy = "999" izz = "999" />
    </inertial>
    <visual>
      <origin xyz="0.5 0 0.5" rpy="0 0 0"/>
      <geometry>
        <box size="1 5 1"/>
      </geometry>
      <material name="light_grey"/>
    </visual>
  </link>


  <!-- <<<<<<<<<<<<<<< CART >>>>>>>>>>>>>>> -->
  <joint name="table_to_cart" type="prismatic">
    <parent link="table"/>
    <child link="cart"/>
    <axis xyz="0 1 0"/>
    <origin xyz="1 0 1.02" rpy="0 0 0"/>
    <limit effort="99999" lower="-2" upper="2" velocity="100"/>
  </joint>
  <link name="cart">
    <inertial>
      <mass value="1" />
      <inertia ixx = "999" iyy = "999" izz = "999" />
    </inertial>
    <visual>
      <origin rpy="0 0 0" xyz="0 0 0" />
      <geometry>
        <box size="0.07 0.15 0.04"/>
      </geometry>
      <material name="blue"/>
    </visual>
  </link>


  <!-- <<<<<<<<<<<<<<< POLE >>>>>>>>>>>>>>> -->
  <joint name="cart_to_pole" type="continuous">
    <parent link="cart"/>
    <child link="pole"/>
    <origin xyz="0.05 0.0 0.0" rpy="0.0 0.0 0.0"/>
    <axis xyz="1 0 0"/>
    <limit effort="999" velocity="999"/>
  </joint>
  <link name="pole">
    <inertial>
      <origin xyz="0 0.25 0"/>
      <mass value="0.1" />
      <inertia ixx = "999" iyy = "999" izz = "999" />
    </inertial>
    <visual>
      <origin xyz="0 0.25 0" rpy="0 0 0"/>
      <geometry>
        <box size="0.01 0.5 0.01"/>
      </geometry>
      <material name="orange"/>
    </visual>
  </link>

  <material name="blue">
    <color rgba="0.0 0.0 0.8 1.0"/>
  </material>
  <material name="light_grey">
    <color rgba="0.7 0.7 0.7 1.0"/>
  </material>
  <material name="orange">
    <color rgba="1.0 0.423529411765 0.0392156862745 1.0"/>
  </material>
</robot>

